Workbook

Sheet Read Me
A1: Hawthorn Gardens — BuildLite UAT Master Pack
A3: Purpose | B3: Controlled fictional known-answer development for BuildLite commercial/CVR testing.
A4: Version | B4: v1 commercial design baseline — not yet imported into BuildLite.
A5: Development | B5: Hawthorn Gardens — 24 private homes.
A6: Cost-code basis | B6: BuildLite shipped 210-code master from server/data/cost_codes.json.
A7: Principle | B7: BuildLite should reproduce the Expected CVR; this workbook is the independent control answer.
A8: Deliberate tests | B8: Approved/pending CEs, credits, linked/direct recovery, material overspend, unbudgeted posting, forecast savings/overspends, actuals vs certificates.
A9: Blue font | B9: Hardcoded fictional UAT input.
A10: Green font | B10: Cross-sheet formula/link.
A11: Black font | B11: Calculation/formula.
A12: Important | B12: Fictional data for software testing only; not a market appraisal or investment case.

Sheet Development Setup
A1: Development Setup
A3: Field | B3: Value
A4: Development | B4: Hawthorn Gardens
A5: Developer | B5: BuildLite Homes Ltd
A6: Location | B6: Midlands (fictional)
A7: Units | B7: 24
A8: Private Units | B8: 24
A9: Affordable Units | B9: 0
A10: Start Date | B10: 46113
A11: Target Completion | B11: 46660
A12: CVR Date | B12: 46326
A13: GDV | B13: 8341500
A14: Purpose | B14: Permanent known-answer UAT development for BuildLite commercial/CVR testing
A16: House Type | B16: Beds | C16: Approx ft² | D16: Plots | E16: No. Units
A17: The Ash | B17: 2 bed | C17: 750 | D17: 1-4 | E17: 4
A18: The Birch | B18: 3 bed | C18: 950 | D18: 5-12 | E18: 8
A19: The Cedar | B19: 3 bed | C19: 1050 | D19: 13-18 | E19: 6
A20: The Oak | B20: 4 bed | C20: 1350 | D20: 19-24 | E20: 6

Sheet Cost Code Master
A1: BuildLite Cost Code Master — 210 Codes
A3: Cost Code | B3: Sub-Heading | C3: Trade | D3: Element | E3: Used in Hawthorn? | F3: Original Budget (£) | G3: Source
A4: 1100 | B4: Land | C4: Vendor | D4: Land Cost | E4: Yes | F4: 1650000 | G4: BuildLite repo master / fictional UAT assumption
A5: 1110 | B5: Land | C5: GOV | D5: VAT on Land Purchase | E5: No | F5: 0 | G5: BuildLite repo master / fictional UAT assumption
A6: 1120 | B6: Land | C6: GOV | D6: Stamp Duty - Incl VAT if applicable | E6: Yes | F6: 85000 | G6: BuildLite repo master / fictional UAT assumption
A7: 1130 | B7: Land | C7: Consultant | D7: Legal Fees - Solicitor | E7: Yes | F7: 25000 | G7: BuildLite repo master / fictional UAT assumption
A8: 1140 | B8: Land | C8: Consultant | D8: Option Fees | E8: No | F8: 0 | G8: BuildLite repo master / fictional UAT assumption
A9: 1150 | B9: Land | C9: Consultant | D9: Selling Agent Fees - | E9: No | F9: 0 | G9: BuildLite repo master / fictional UAT assumption
A10: 1160 | B10: Land | C10: Vendor | D10: Sundy Land Costs - Overage Payments | E10: No | F10: 0 | G10: BuildLite repo master / fictional UAT assumption
A11: 1170 | B11: Fees | C11: Consultant | D11: Planning Application & Supporting Fees | E11: Yes | F11: 35000 | G11: BuildLite repo master / fictional UAT assumption
A12: 1180 | B12: Fees | C12: Consultant | D12: Site Investigation | E12: Yes | F12: 25000 | G12: BuildLite repo master / fictional UAT assumption
A13: 1190 | B13: Fees | C13: Consultant | D13: Archaeology | E13: Yes | F13: 15000 | G13: BuildLite repo master / fictional UAT assumption
A14: 1200 | B14: Fees | C14: Consultant | D14: Contamination | E14: Yes | F14: 20000 | G14: BuildLite repo master / fictional UAT assumption
A15: 1210 | B15: Fees | C15: Consultant | D15: Design Fees | E15: Yes | F15: 40000 | G15: BuildLite repo master / fictional UAT assumption
... A213: 6280 | B213: Sales | C213: Utility | D213: Utility Bills Pre-Handover | E213: No | F213: 0 | G213: BuildLite repo master / fictional UAT assumption

Sheet Original Budget
A1: Original Development Budget
A3: Cost Code | B3: Sub-Heading | C3: Trade | D3: Element | E3: Original Budget (£) | F3: £/Unit | G3: Active? | H3: Assumption / Test Purpose
A4: 1100 | B4: Land | C4: Vendor | D4: Land Cost | E4: 1650000 | F4: =IF(E4=0,0,E4/24) -> 68750 | G4: Yes | H4: Fictional UAT budget assumption.
A5: 1110 | B5: Land | C5: GOV | D5: VAT on Land Purchase | E5: 0 | F5: =IF(E5=0,0,E5/24) -> 0 | G5: No
A6: 1120 | B6: Land | C6: GOV | D6: Stamp Duty - Incl VAT if applicable | E6: 85000 | F6: =IF(E6=0,0,E6/24) -> 3541.6667 | G6: Yes | H6: Fictional UAT budget assumption.
A7: 1130 | B7: Land | C7: Consultant | D7: Legal Fees - Solicitor | E7: 25000 | F7: =IF(E7=0,0,E7/24) -> 1041.6667 | G7: Yes | H7: Fictional UAT budget assumption.
A8: 1140 | B8: Land | C8: Consultant | D8: Option Fees | E8: 0 | F8: =IF(E8=0,0,E8/24) -> 0 | G8: No
A9: 1150 | B9: Land | C9: Consultant | D9: Selling Agent Fees - | E9: 0 | F9: =IF(E9=0,0,E9/24) -> 0 | G9: No
A10: 1160 | B10: Land | C10: Vendor | D10: Sundy Land Costs - Overage Payments | E10: 0 | F10: =IF(E10=0,0,E10/24) -> 0 | G10: No
A11: 1170 | B11: Fees | C11: Consultant | D11: Planning Application & Supporting Fees | E11: 35000 | F11: =IF(E11=0,0,E11/24) -> 1458.3333 | G11: Yes | H11: Fictional UAT budget assumption.
A12: 1180 | B12: Fees | C12: Consultant | D12: Site Investigation | E12: 25000 | F12: =IF(E12=0,0,E12/24) -> 1041.6667 | G12: Yes | H12: Fictional UAT budget assumption.
A13: 1190 | B13: Fees | C13: Consultant | D13: Archaeology | E13: 15000 | F13: =IF(E13=0,0,E13/24) -> 625 | G13: Yes | H13: Fictional UAT budget assumption.
A14: 1200 | B14: Fees | C14: Consultant | D14: Contamination | E14: 20000 | F14: =IF(E14=0,0,E14/24) -> 833.33333 | G14: Yes | H14: Fictional UAT budget assumption.
A15: 1210 | B15: Fees | C15: Consultant | D15: Design Fees | E15: 40000 | F15: =IF(E15=0,0,E15/24) -> 1666.6667 | G15: Yes | H15: Fictional UAT budget assumption.
A16: 1220 | B16: Fees | C16: Consultant | D16: Architects - Post Planning | E16: 55000 | F16: =IF(E16=0,0,E16/24) -> 2291.6667 | G16: Yes | H16: Fictional UAT budget assumption.
A17: 1230 | B17: Fees | C17: Consultant | D17: Engineers | E17: 75000 | F17: =IF(E17=0,0,E17/24) -> 3125 | G17: Yes | H17: Fictional UAT budget assumption.
A18: 1240 | B18: Fees | C18: Consultant | D18: Surveys | E18: 20000 | F18: =IF(E18=0,0,E18/24) -> 833.33333 | G18: Yes | H18: Fictional UAT budget assumption.
A19: 1250 | B19: Fees | C19: Consultant | D19: NHBC Bond Fees | E19: 25000 | F19: =IF(E19=0,0,E19/24) -> 1041.6667 | G19: Yes | H19: Fictional UAT budget assumption.
A20: 1260 | B20: Fees | C20: Consultant | D20: Insurance | E20: 15000 | F20: =IF(E20=0,0,E20/24) -> 625 | G20: Yes | H20: Fictional UAT budget assumption.
A21: 1270 | B21: Fees | C21: Consultant | D21: Planning Consultants | E21: 0 | F21: =IF(E21=0,0,E21/24) -> 0 | G21: No
A22: 1280 | B22: Fees | C22: Consultant | D22: Highways Consultants | E22: 20000 | F22: =IF(E22=0,0,E22/24) -> 833.33333 | G22: Yes | H22: Fictional UAT budget assumption.
A23: 1290 | B23: Fees | C23: Consultant | D23: Environmental Consultants | E23: 15000 | F23: =IF(E23=0,0,E23/24) -> 625 | G23: Yes | H23: Fictional UAT budget assumption.
A24: 1300 | B24: Fees | C24: Consultant | D24: M&E Consultants | E24: 10000 | F24: =IF(E24=0,0,E24/24) -> 416.66667 | G24: Yes | H24: Fictional UAT budget assumption.
A25: 1310 | B25: Fees | C25: LA | D25: Sewers Adoption (s104): | E25: 18000 | F25: =IF(E25=0,0,E25/24) -> 750 | G25: Yes | H25: Fictional UAT budget assumption.
A26: 1320 | B26: Fees | C26: LA | D26: Highways Adoption (s18/38): | E26: 22000 | F26: =IF(E26=0,0,E26/24) -> 916.66667 | G26: Yes | H26: Fictional UAT budget assumption.
A27: 1330 | B27: Fees | C27: LA | D27: S278 Fees | E27: 12000 | F27: =IF(E27=0,0,E27/24) -> 500 | G27: Yes | H27: Fictional UAT budget assumption.
A28: 1340 | B28: Fees | C28: LA | D28: Building Regulation Fees | E28: 22000 | F28: =IF(E28=0,0,E28/24) -> 916.66667 | G28: Yes | H28: Fictional UAT budget assumption.
A29: 1350 | B29: Fees | C29: LA | D29: Planning Fees | E29: 0 | F29: =IF(E29=0,0,E29/24) -> 0 | G29: No
A30: 1360 | B30: Fees | C30: Consultant | D30: SAP Calculations | E30: 10000 | F30: =IF(E30=0,0,E30/24) -> 416.66667 | G30: Yes | H30: Fictional UAT budget assumption.
A31: 1370 | B31: Fees | C31: Consultant | D31: Air Tests | E31: 7500 | F31: =IF(E31=0,0,E31/24) -> 312.5 | G31: Yes | H31: Fictional UAT budget assumption.
A32: 1380 | B32: Fees | C32: Consultant | D32: NHBC - Warranty & Build control | E32: 48000 | F32: =IF(E32=0,0,E32/24) -> 2000 | G32: Yes | H32: Fictional UAT budget assumption.
A33: 1400 | B33: Fees | C33: Lender | D33: Finance lenders Fees | E33: 0 | F33: =IF(E33=0,0,E33/24) -> 0 | G33: No
A34: 1410 | B34: Fees | C34: Consultant | D34: Other Fees | E34: 12500 | F34: =IF(E34=0,0,E34/24) -> 520.83333 | G34: Yes | H34: Fictional UAT budget assumption.
A35: 2100 | B35: Prelims | C35: Direct | D35: Site Manager | E35: 95000 | F35: =IF(E35=0,0,E35/24) -> 3958.3333 | G35: Yes | H35: Fictional UAT budget assumption.
A36: 2101 | B36: Prelims | C36: Direct | D36: Assistant Site Manager | E36: 55000 | F36: =IF(E36=0,0,E36/24) -> 2291.6667 | G36: Yes | H36: Fictional UAT budget assumption.
A37: 2110 | B37: Prelims | C37: Direct | D37: Direct Staff Bonuses | E37: 12000 | F37: =IF(E37=0,0,E37/24) -> 500 | G37: Yes | H37: Fictional UAT budget assumption.
A38: 2120 | B38: Prelims | C38: Direct | D38: Direct Staff NIC on Bonuses | E38: 0 | F38: =IF(E38=0,0,E38/24) -> 0 | G38: No
A39: 2130 | B39: Prelims | C39: Direct | D39: NIC on Salary | E39: 18000 | F39: =IF(E39=0,0,E39/24) -> 750 | G39: Yes | H39: Fictional UAT budget assumption.
A40: 2140 | B40: Prelims | C40: Direct | D40: Pension | E40: 9000 | F40: =IF(E40=0,0,E40/24) -> 375 | G40: Yes | H40: Fictional UAT budget assumption.
A41: 2150 | B41: Prelims | C41: Direct | D41: Forklift Driver - Direct | E41: 0 | F41: =IF(E41=0,0,E41/24) -> 0 | G41: No
...

Sheet Package PO Plan
A1: Package / Purchase Order Plan
A3: PO Number | B3: Cost Code | C3: Trade / Element | D3: Supplier | E3: Order Type | F3: Original PO (£) | G3: Status | H3: Budget (£) | I3: Headroom/(Overbuy) (£) | J3: Purpose
A4: S-HG001 | B4: 3100 | C4: Sub-Con — Groundworker Prelims | D4: J&M Civils Ltd | E4: S | F4: 115000 | G4: Approved | H4: 120000 | I4: =H4-F4 -> 5000 | J4: Infrastructure
A5: S-HG002 | B5: 3500 | C5: Sub-con — Service Trenches & Ducts | D5: J&M Civils Ltd | E5: S | F5: 90000 | G5: Approved | H5: 95000 | I5: =H5-F5 -> 5000 | J5: Plot services
A6: S-HG003 | B6: 3520 | C6: Sub-con — Plot Drainage incl Internal Drainage | D6: J&M Civils Ltd | E6: S | F6: 155000 | G6: Approved | H6: 165000 | I6: =H6-F6 -> 10000 | J6: Plot drainage
A7: S-HG004 | B7: 4110 | C7: Sub-Con — Scaffolding | D7: HighReach Scaffolding Ltd | E7: S | F7: 78000 | G7: Approved | H7: 82000 | I7: =H7-F7 -> 4000 | J7: Scaffolding
A8: S-HG005 | B8: 4120 | C8: Sub-Con — Brickwork | D8: Midlands Brickwork Ltd | E8: S | F8: 235000 | G8: Approved | H8: 245000 | I8: =H8-F8 -> 10000 | J8: Brickwork labour
A9: S-HG006 | B9: 4130 | C9: Sub-Con — Carpentry | D9: Oakline Carpentry Ltd | E9: S | F9: 175000 | G9: Approved | H9: 180000 | I9: =H9-F9 -> 5000 | J9: Carpentry labour
A10: S-HG007 | B10: 4180 | C10: Sub-Con — Roofing | D10: Peak Roofing Ltd | E10: S | F10: 110000 | G10: Approved | H10: 115000 | I10: =H10-F10 -> 5000 | J10: Roofing
A11: S-HG008 | B11: 4200 | C11: Sub-Con — Windows and Ext. Doors | D11: Clearview Windows Ltd | E11: S | F11: 122000 | G11: Approved | H11: 125000 | I11: =H11-F11 -> 3000 | J11: Windows & external doors
A12: S-HG009 | B12: 4230 | C12: Sub-Con — Plastering & Drylining | D12: SmoothFinish Drylining Ltd | E12: S | F12: 125000 | G12: Approved | H12: 128000 | I12: =H12-F12 -> 3000 | J12: Drylining
A13: S-HG010 | B13: 4240 | C13: Sub-Con — Plumbing & Heating | D13: FlowRight Plumbing Ltd | E13: S | F13: 185000 | G13: Approved | H13: 190000 | I13: =H13-F13 -> 5000 | J13: Plumbing & heating
A14: S-HG011 | B14: 4250 | C14: Sub-Con — Electrical | D14: Voltwise Electrical Ltd | E14: S | F14: 140000 | G14: Approved | H14: 145000 | I14: =H14-F14 -> 5000 | J14: Electrical
A15: S-HG012 | B15: 4260 | C15: Sub-Con — Kitchen Fitting | D15: KitchenCraft Installations Ltd | E15: S | F15: 112000 | G15: Approved | H15: 118000 | I15: =H15-F15 -> 6000 | J15: Kitchen fitting
... A29: M-HG007 | B29: 4270 | C29: Sub-Con — Appliances | D29: Home Appliance Supply | E29: M | F29: 55000 | G29: Approved | H29: 58000 | I29: =H29-F29 -> 3000 | J29: Appliances

Sheet Commercial Events
A1: Commercial Events — Designed UAT Scenarios
A3: Event No. | B3: Cost Code | C3: Supplier | D3: Event Type | E3: Description | F3: Value (£) | G3: Status | H3: Financial Treatment | I3: Relationship Type | J3: Linked Event | K3: CCV Impact (£) | L3: UAT Purpose
A4: CE-HG001 | B4: 3100 | C4: J&M Civils Ltd | D4: variation | E4: Unexpected soft spots and stone replacement | F4: 35000 | G4: approved | H4: contractAmendment | K4: 35000 | L4: Groundworks approved overspend
A5: CE-HG002 | B5: 3100 | C5: J&M Civils Ltd | D5: variation | E5: Additional muck-away risk | F5: 20000 | G5: submitted | H5: contractAmendment | K5: 0 | L5: Pending risk
A6: CE-HG003 | B6: 4120 | C6: Midlands Brickwork Ltd | D6: variation | E6: Additional masonry detailing | F6: 5000 | G6: approved | H6: contractAmendment | K6: 5000 | L6: Small approved uplift
A7: CE-HG004 | B7: 4250 | C7: Voltwise Electrical Ltd | D7: salesUpgrade | E7: Customer electrical upgrades | F7: 12000 | G7: approved | H7: contractAmendment | K7: 12000 | L7: Payable customer extras
A8: CE-HG005 | B8: 4250 | C8: Voltwise Electrical Ltd | D8: variation | E8: Repair dryliner damage | F8: 4000 | G8: approved | H8: contractAmendment | I8: origin | J8: CE-HG006 | K8: 4000 | L8: Payable origin
A9: CE-HG006 | B9: 4230 | C9: SmoothFinish Drylining Ltd | D9: contraCharge | E9: Repair dryliner damage | F9: -4000 | G9: approved | H9: recoverableDeduction | I9: recovery | J9: CE-HG005 | K9: 0 | L9: Linked recovery; payment-only
A10: CE-HG007 | B10: 4240 | C10: FlowRight Plumbing Ltd | D10: credit | E10: Omitted secondary towel radiators | F10: -6000 | G10: approved | H10: contractAmendment | K10: -6000 | L10: Approved credit
A11: CE-HG008 | B11: 4200 | C11: Clearview Windows Ltd | D11: credit | E11: Revised patio-door specification | F11: -3000 | G11: approved | H11: contractAmendment | K11: -3000 | L11: Approved credit
A12: CE-HG009 | B12: 4180 | C12: Peak Roofing Ltd | D12: variation | E12: Revised valley detail | F12: 8000 | G12: submitted | H12: contractAmendment | K12: 0 | L12: Pending variation
A13: CE-HG010 | B13: 4360 | C13: WipeRight Cleaning Ltd | D13: contraCharge | E13: Damage to finished flooring | F13: -1500 | G13: approved | H13: recoverableDeduction | I13: recovery | K13: 0 | L13: Direct recovery
A14: CE-HG011 | B14: 4340 | C14: PerfectFinish Decorating Ltd | D14: variation | E14: Additional colour changes | F14: 2000 | G14: draft | H14: contractAmendment | K14: 0 | L14: Draft variation
A15: CE-HG012 | B15: 5260 | C15: J&M Civils Ltd | D15: variation | E15: Additional traffic-management phase | F15: 6500 | G15: approved | H15: contractAmendment | K15: 6500 | L15: Approved S278 uplift

Sheet Certificates
A1: Payment Certificate History
A3: PO Number | B3: Certificate No. | C3: Status | D3: Gross Works (£) | E3: Retention (£) | F3: Recovery Deduction (£) | G3: Net Payment (£) | H3: Certificate Date | I3: Notes | J3: Source
A4: S-HG001 | B4: 1 | C4: Locked | D4: 45000 | E4: 2250 | F4: 0 | G4: 42750 | H4: 46203 | J4: Fictional UAT certificate history
A5: S-HG001 | B5: 2 | C5: Locked | D5: 52000 | E5: 2600 | F5: 0 | G5: 49400 | H5: 46265 | J5: Fictional UAT certificate history
A6: S-HG004 | B6: 1 | C6: Locked | D6: 24000 | E6: 1200 | F6: 0 | G6: 22800 | H6: 46234 | J6: Fictional UAT certificate history
A7: S-HG005 | B7: 1 | C7: Locked | D7: 28500 | E7: 1425 | F7: 0 | G7: 27075 | H7: 46142 | J7: Fictional UAT certificate history
A8: S-HG005 | B8: 2 | C8: Locked | D8: 34000 | E8: 1700 | F8: 0 | G8: 32300 | H8: 46173 | J8: Fictional UAT certificate history
A9: S-HG005 | B9: 3 | C9: Locked | D9: 31500 | E9: 1575 | F9: 0 | G9: 29925 | H9: 46203 | J9: Fictional UAT certificate history
A10: S-HG005 | B10: 4 | C10: Locked | D10: 18000 | E10: 900 | F10: 0 | G10: 17100 | H10: 46234 | J10: Fictional UAT certificate history
A11: S-HG006 | B11: 1 | C11: Locked | D11: 42000 | E11: 2100 | F11: 0 | G11: 39900 | H11: 46234 | J11: Fictional UAT certificate history
A12: S-HG006 | B12: 2 | C12: Locked | D12: 35000 | E12: 1750 | F12: 0 | G12: 33250 | H12: 46295 | J12: Fictional UAT certificate history
A13: S-HG007 | B13: 1 | C13: Locked | D13: 30000 | E13: 1500 | F13: 0 | G13: 28500 | H13: 46295 | J13: Fictional UAT certificate history
A14: S-HG008 | B14: 1 | C14: Locked | D14: 36000 | E14: 1800 | F14: 0 | G14: 34200 | H14: 46295 | J14: Fictional UAT certificate history
A15: S-HG009 | B15: 1 | C15: Locked | D15: 32000 | E15: 1600 | F15: 0 | G15: 30400 | H15: 46265 | J15: Fictional UAT certificate history
A16: S-HG009 | B16: 2 | C16: Locked | D16: 28000 | E16: 1400 | F16: -1500 | G16: 25100 | H16: 46326 | I16: Partial linked recovery deduction — payment-only. | J16: Fictional UAT certificate history
A17: S-HG010 | B17: 1 | C17: Locked | D17: 48000 | E17: 2400 | F17: 0 | G17: 45600 | H17: 46265 | J17: Fictional UAT certificate history
A18: S-HG010 | B18: 2 | C18: Locked | D18: 39000 | E18: 1950 | F18: 0 | G18: 37050 | H18: 46326 | J18: Fictional UAT certificate history
A19: S-HG011 | B19: 1 | C19: Locked | D19: 34000 | E19: 1700 | F19: 0 | G19: 32300 | H19: 46234 | J19: Fictional UAT certificate history
A20: S-HG011 | B20: 2 | C20: Locked | D20: 26000 | E20: 1300 | F20: 0 | G20: 24700 | H20: 46295 | J20: Fictional UAT certificate history
A21: S-HG012 | B21: 1 | C21: Locked | D21: 30000 | E21: 1500 | F21: 0 | G21: 28500 | H21: 46295 | J21: Fictional UAT certificate history
A22: S-HG013 | B22: 1 | C22: Locked | D22: 28000 | E22: 1400 | F22: 0 | G22: 26600 | H22: 46265 | J22: Fictional UAT certificate history
A23: S-HG014 | B23: 1 | C23: Locked | D23: 18000 | E23: 900 | F23: 0 | G23: 17100 | H23: 46295 | J23: Fictional UAT certificate history
A24: S-HG018 | B24: 1 | C24: Locked | D24: 56000 | E24: 2800 | F24: 0 | G24: 53200 | H24: 46203 | J24: Fictional UAT certificate history

Sheet Ledger
A1: Cost Ledger — Fictional Accounting Transactions
A3: Posting Date | B3: Cost Code | C3: Sub-Heading | D3: Element | E3: Supplier | F3: Reference | G3: Description | H3: Debit (£) | I3: UAT Flag
A4: 46142 | B4: 1100 | C4: Land | D4: Land Cost | E4: Vendor | F4: HG-1100-01 | G4: Land Cost - ledger posting 1 | H4: 371250
A5: 46173 | B5: 1100 | C5: Land | D5: Land Cost | E5: Vendor | F5: HG-1100-02 | G5: Land Cost - ledger posting 2 | H5: 396000
A6: 46204 | B6: 1100 | C6: Land | D6: Land Cost | E6: Vendor | F6: HG-1100-03 | G6: Land Cost - ledger posting 3 | H6: 420750
A7: 46235 | B7: 1100 | C7: Land | D7: Land Cost | E7: Vendor | F7: HG-1100-04 | G7: Land Cost - ledger posting 4 | H7: 462000
A8: 46142 | B8: 1120 | C8: Land | D8: Stamp Duty - Incl VAT if applicable | E8: GOV | F8: HG-1120-01 | G8: Stamp Duty - Incl VAT if applicable - ledger posting 1 | H8: 25500
A9: 46173 | B9: 1120 | C9: Land | D9: Stamp Duty - Incl VAT if applicable | E9: GOV | F9: HG-1120-02 | G9: Stamp Duty - Incl VAT if applicable - ledger posting 2 | H9: 27200
A10: 46204 | B10: 1120 | C10: Land | D10: Stamp Duty - Incl VAT if applicable | E10: GOV | F10: HG-1120-03 | G10: Stamp Duty - Incl VAT if applicable - ledger posting 3 | H10: 32300
A11: 46142 | B11: 1130 | C11: Land | D11: Legal Fees - Solicitor | E11: Consultant | F11: HG-1130-01 | G11: Legal Fees - Solicitor - ledger posting 1 | H11: 9900
A12: 46173 | B12: 1130 | C12: Land | D12: Legal Fees - Solicitor | E12: Consultant | F12: HG-1130-02 | G12: Legal Fees - Solicitor - ledger posting 2 | H12: 12100
A13: 46142 | B13: 1170 | C13: Fees | D13: Planning Application & Supporting Fees | E13: Consultant | F13: HG-1170-01 | G13: Planning Application & Supporting Fees - ledger posting 1 | H13: 15750
A14: 46173 | B14: 1170 | C14: Fees | D14: Planning Application & Supporting Fees | E14: Consultant | F14: HG-1170-02 | G14: Planning Application & Supporting Fees - ledger posting 2 | H14: 19250
A15: 46142 | B15: 1180 | C15: Fees | D15: Site Investigation | E15: Consultant | F15: HG-1180-01 | G15: Site Investigation - ledger posting 1 | H15: 11250
... A130: 46204 | B130: 5350 | C130: Contributions | D130: CIL | E130: LA | F130: HG-5350-03 | G130: CIL - ledger posting 3 | H130: 21850
A131: 46142 | B131: 4290 | C131: Super-Structure | D131: Wardrobes | E131: Furniture supplier (mispost) | F131: HG-4290-01 | G131: Wardrobes - ledger posting 1 | H131: 8500 | I131: DELIBERATE WRONG-CODE POSTING
A132: 46142 | B132: 6140 | C132: Sales | D132: Advertising | E132: Consultant | F132: HG-6140-01 | G132: Advertising - ledger posting 1 | H132: 10000
A133: 46142 | B133: 6160 | C133: Sales | D133: Showhouse Furnishing - Showhome 1 | E133: Sub-contract | F133: HG-6160-01 | G133: Showhouse Furnishing - Showhome 1 - ledger posting 1 | H133: 8100
A134: 46173 | B134: 6160 | C134: Sales | D134: Showhouse Furnishing - Showhome 1 | E134: Sub-contract | F134: HG-6160-02 | G134: Showhouse Furnishing - Showhome 1 - ledger posting 2 | H134: 9900

Sheet Forecast Adjustments
A1: QS Forecast — Known-Answer Inputs
A3: Cost Code | B3: Element | C3: Original Budget (£) | D3: Current Commitment (£) | E3: Ledger Actual (£) | F3: Expected FFC (£) | G3: Variance to Budget (£) | H3: QS Rationale
A4: 1100 | B4: Land Cost | C4: 1650000 | D4: =SUMIF('Package PO Plan'!$B:$B,A4,'Package PO Plan'!$F:$F)+SUMIF('Commercial Events'!$B:$B,A4,'Commercial Events'!$K:$K) -> 0 | E4: =SUMIF(Ledger!$B:$B,A4,Ledger!$H:$H) -> 1650000 | F4: =MAX(C4,D4,E4) -> 1650000 | G4: =C4-F4 -> 0 | H4: Forecast at strongest current commercial baseline unless noted.
A5: 1120 | B5: Stamp Duty - Incl VAT if applicable | C5: 85000 | D5: =SUMIF('Package PO Plan'!$B:$B,A5,'Package PO Plan'!$F:$F)+SUMIF('Commercial Events'!$B:$B,A5,'Commercial Events'!$K:$K) -> 0 | E5: =SUMIF(Ledger!$B:$B,A5,Ledger!$H:$H) -> 85000 | F5: =MAX(C5,D5,E5) -> 85000 | G5: =C5-F5 -> 0 | H5: Forecast at strongest current commercial baseline unless noted.
A6: 1130 | B6: Legal Fees - Solicitor | C6: 25000 | D6: =SUMIF('Package PO Plan'!$B:$B,A6,'Package PO Plan'!$F:$F)+SUMIF('Commercial Events'!$B:$B,A6,'Commercial Events'!$K:$K) -> 0 | E6: =SUMIF(Ledger!$B:$B,A6,Ledger!$H:$H) -> 22000 | F6: =MAX(C6,D6,E6) -> 25000 | G6: =C6-F6 -> 0 | H6: Forecast at strongest current commercial baseline unless noted.
A7: 1170 | B7: Planning Application & Supporting Fees | C7: 35000 | D7: =SUMIF('Package PO Plan'!$B:$B,A7,'Package PO Plan'!$F:$F)+SUMIF('Commercial Events'!$B:$B,A7,'Commercial Events'!$K:$K) -> 0 | E7: =SUMIF(Ledger!$B:$B,A7,Ledger!$H:$H) -> 35000 | F7: =MAX(C7,D7,E7) -> 35000 | G7: =C7-F7 -> 0 | H7: Forecast at strongest current commercial baseline unless noted.
A8: 1180 | B8: Site Investigation | C8: 25000 | D8: =SUMIF('Package PO Plan'!$B:$B,A8,'Package PO Plan'!$F:$F)+SUMIF('Commercial Events'!$B:$B,A8,'Commercial Events'!$K:$K) -> 0 | E8: =SUMIF(Ledger!$B:$B,A8,Ledger!$H:$H) -> 25000 | F8: =MAX(C8,D8,E8) -> 25000 | G8: =C8-F8 -> 0 | H8: Forecast at strongest current commercial baseline unless noted.
A9: 1190 | B9: Archaeology | C9: 15000 | D9: =SUMIF('Package PO Plan'!$B:$B,A9,'Package PO Plan'!$F:$F)+SUMIF('Commercial Events'!$B:$B,A9,'Commercial Events'!$K:$K) -> 0 | E9: =SUMIF(Ledger!$B:$B,A9,Ledger!$H:$H) -> 15000 | F9: =MAX(C9,D9,E9) -> 15000 | G9: =C9-F9 -> 0 | H9: Forecast at strongest current commercial baseline unless noted.
A10: 1200 | B10: Contamination | C10: 20000 | D10: =SUMIF('Package PO Plan'!$B:$B,A10,'Package PO Plan'!$F:$F)+SUMIF('Commercial Events'!$B:$B,A10,'Commercial Events'!$K:$K) -> 0 | E10: =SUMIF(Ledger!$B:$B,A10,Ledger!$H:$H) -> 0 | F10: =MAX(C10,D10,E10) -> 20000 | G10: =C10-F10 -> 0 | H10: Forecast at strongest current commercial baseline unless noted.
A11: 1210 | B11: Design Fees | C11: 40000 | D11: =SUMIF('Package PO Plan'!$B:$B,A11,'Package PO Plan'!$F:$F)+SUMIF('Commercial Events'!$B:$B,A11,'Commercial Events'!$K:$K) -> 0 | E11: =SUMIF(Ledger!$B:$B,A11,Ledger!$H:$H) -> 28000 | F11: =MAX(C11,D11,E11) -> 40000 | G11: =C11-F11 -> 0 | H11: Forecast at strongest current commercial baseline unless noted.
A12: 1220 | B12: Architects - Post Planning | C12: 55000 | D12: =SUMIF('Package PO Plan'!$B:$B,A12,'Package PO Plan'!$F:$F)+SUMIF('Commercial Events'!$B:$B,A12,'Commercial Events'!$K:$K) -> 0 | E12: =SUMIF(Ledger!$B:$B,A12,Ledger!$H:$H) -> 25000 | F12: =MAX(C12,D12,E12) -> 55000 | G12: =C12-F12 -> 0 | H12: Forecast at strongest current commercial baseline unless noted.
A13: 1230 | B13: Engineers | C13: 75000 | D13: =SUMIF('Package PO Plan'!$B:$B,A13,'Package PO Plan'!$F:$F)+SUMIF('Commercial Events'!$B:$B,A13,'Commercial Events'!$K:$K) -> 0 | E13: =SUMIF(Ledger!$B:$B,A13,Ledger!$H:$H) -> 42000 | F13: =MAX(C13,D13,E13) -> 75000 | G13: =C13-F13 -> 0 | H13: Forecast at strongest current commercial baseline unless noted.
A14: 1240 | B14: Surveys | C14: 20000 | D14: =SUMIF('Package PO Plan'!$B:$B,A14,'Package PO Plan'!$F:$F)+SUMIF('Commercial Events'!$B:$B,A14,'Commercial Events'!$K:$K) -> 0 | E14: =SUMIF(Ledger!$B:$B,A14,Ledger!$H:$H) -> 0 | F14: =MAX(C14,D14,E14) -> 20000 | G14: =C14-F14 -> 0 | H14: Forecast at strongest current commercial baseline unless noted.
A15: 1250 | B15: NHBC Bond Fees | C15: 25000 | D15: =SUMIF('Package PO Plan'!$B:$B,A15,'Package PO Plan'!$F:$F)+SUMIF('Commercial Events'!$B:$B,A15,'Commercial Events'!$K:$K) -> 0 | E15: =SUMIF(Ledger!$B:$B,A15,Ledger!$H:$H) -> 0 | F15: =MAX(C15,D15,E15) -> 25000 | G15: =C15-F15 -> 0 | H15: Forecast at strongest current commercial baseline unless noted.
... A48: 2330 | B48: Security - Cameras | C48: 15000 | D48: =SUMIF('Package PO Plan'!$B:$B,A48,'Package PO Plan'!$F:$F)+SUMIF('Commercial Events'!$B:$B,A48,'Commercial Events'!$K:$K) -> 0 | E48: =SUMIF(Ledger!$B:$B,A48,Ledger!$H:$H) -> 5000 | F48: =MAX(C48,D48,E48) -> 15000 | G48: =C48-F48 -> 0 | H48: Forecast at strongest current commercial baseline unless noted.
A49: 2350 | B49: Contingency | C49: 30000 | D49: =SUMIF('Package PO Plan'!$B:$B,A49,'Package PO Plan'!$F:$F)+SUMIF('Commercial Events'!$B:$B,A49,'Commercial Events'!$K:$K) -> 0 | E49: =SUMIF(Ledger!$B:$B,A49,Ledger!$H:$H) -> 0 | F49: 20000 | G49: =C49-F49 -> 10000 | H49: Only £20k of £30k contingency expected to be used.
A50: 3100 | B50: Groundworker Prelims | C50: 120000 | D50: =SUMIF('Package PO Plan'!$B:$B,A50,'Package PO Plan'!$F:$F)+SUMIF('Commercial Events'!$B:$B,A50,'Commercial Events'!$K:$K) -> 150000 | E50: =SUMIF(Ledger!$B:$B,A50,Ledger!$H:$H) -> 112000 | F50: 155000 | G50: =C50-F50 -> -35000 | H50: Soft-ground approved CE plus unresolved muck-away risk.
A51: 3110 | B51: Duct Crossings | C51: 35000 | D51: =SUMIF('Package PO Plan'!$B:$B,A51,'Package PO Plan'!$F:$F)+SUMIF('Commercial Events'!$B:$B,A51,'Commercial Events'!$K:$K) -> 0 | E51: =SUMIF(Ledger!$B:$B,A51,Ledger!$H:$H) -> 18000 | F51: =MAX(C51,D51,E51) -> 35000 | G51: =C51-F51 -> 0 | H51: Forecast at strongest current commercial baseline unless noted.
A52: 3120 | B52: Footpaths to Base | C52: 55000 | D52: =SUMIF('Package PO Plan'!$B:$B,A52,'Package PO Plan'!$F:$F)+SUMIF('Commercial Events'!$B:$B,A52,'Commercial Events'!$K:$K) -> 0 | E52: =SUMIF(Ledger!$B:$B,A52,Ledger!$H:$H) -> 18000 | F52: =MAX(C52,D52,E52) -> 55000 | G52: =C52-F52 -> 0 | H52: Forecast at strongest current commercial baseline unless noted.
A53: 3160 | B53: R&S - REMEDIALS: | C53: 20000 | D53: =SUMIF('Package PO Plan'!$B:$B,A53,'Package PO Plan'!$F:$F)+SUMIF('Commercial Events'!$B:$B,A53,'Commercial Events'!$K:$K) -> 0 | E53: =SUMIF(Ledger!$B:$B,A53,Ledger!$H:$H) -> 0 | F53: =MAX(C53,D53,E53) -> 20000 | G53: =C53-F53 -> 0 | H53: Forecast at strongest current commercial baseline unless noted.
A54: 3170 | B54: Electricity Mains - Mains & Connections | C54: 55000 | D54: =SUMIF('Package PO Plan'!$B:$B,A54,'Package PO Plan'!$F:$F)+SUMIF('Commercial Events'!$B:$B,A54,'Commercial Events'!$K:$K) -> 0 | E54: =SUMIF(Ledger!$B:$B,A54,Ledger!$H:$H) -> 22000 | F54: =MAX(C54,D54,E54) -> 55000 | G54: =C54-F54 -> 0 | H54: Forecast at strongest current commercial baseline unless noted.
A55: 3190 | B55: Water Mains - Laying & Connection | C55: 35000 | D55: =SUMIF('Package PO Plan'!$B:$B,A55,'Package PO Plan'!$F:$F)+SUMIF('Commercial Events'!$B:$B,A55,'Commercial Events'!$K:$K) -> 0 | E55: =SUMIF(Ledger!$B:$B,A55,Ledger!$H:$H) -> 14000 | F55: =MAX(C55,D55,E55) -> 35000 | G55: =C55-F55 -> 0 | H55: Forecast at strongest current commercial baseline unless noted.
A56: 3200 | B56: Telephone Mains | C56: 15000 | D56: =SUMIF('Package PO Plan'!$B:$B,A56,'Package PO Plan'!$F:$F)+SUMIF('Commercial Events'!$B:$B,A56,'Commercial Events'!$K:$K) -> 0 | E56: =SUMIF(Ledger!$B:$B,A56,Ledger!$H:$H) -> 0 | F56: =MAX(C56,D56,E56) -> 15000 | G56: =C56-F56 -> 0 | H56: Forecast at strongest current commercial baseline unless noted.
A57: 3210 | B57: Fibre | C57: 15000 | D57: =SUMIF('Package PO Plan'!$B:$B,A57,'Package PO Plan'!$F:$F)+SUMIF('Commercial Events'!$B:$B,A57,'Commercial Events'!$K:$K) -> 0 | E57: =SUMIF(Ledger!$B:$B,A57,Ledger!$H:$H) -> 0 | F57: =MAX(C57,D57,E57) -> 15000 | G57: =C57-F57 -> 0 | H57: Forecast at strongest current commercial baseline unless noted.
A58: 3220 | B58: Street Lights - Supply & Install Columns | C58: 36000 | D58: =SUMIF('Package PO Plan'!$B:$B,A58,'Package PO Plan'!$F:$F)+SUMIF('Commercial Events'!$B:$B,A58,'Commercial Events'!$K:$K) -> 0 | E58: =SUMIF(Ledger!$B:$B,A58,Ledger!$H:$H) -> 0 | F58: =MAX(C58,D58,E58) -> 36000 | G58: =C58-F58 -> 0 | H58: Forecast at strongest current commercial baseline unless noted.
A59: 3230 | B59: Street Lighting Connections | C59: 9000 | D59: =SUMIF('Package PO Plan'!$B:$B,A59,'Package PO Plan'!$F:$F)+SUMIF('Commercial Events'!$B:$B,A59,'Commercial Events'!$K:$K) -> 0 | E59: =SUMIF(Ledger!$B:$B,A59,Ledger!$H:$H) -> 0 | F59: =MAX(C59,D59,E59) -> 9000 | G59: =C59-F59 -> 0 | H59: Forecast at strongest current commercial baseline unless noted.
A60: 3240 | B60: Public Open Space & Play Areas | C60: 45000 | D60: =SUMIF('Package PO Plan'!$B:$B,A60,'Package PO Plan'!$F:$F)+SUMIF('Commercial Events'!$B:$B,A60,'Commercial Events'!$K:$K) -> 0 | E60: =SUMIF(Ledger!$B:$B,A60,Ledger!$H:$H) -> 0 | F60: =MAX(C60,D60,E60) -> 45000 | G60: =C60-F60 -> 0 | H60: Forecast at strongest current commercial baseline unless noted.
A61: 3260 | B61: Hard Landscaping | C61: 35000 | D61: =SUMIF('Package PO Plan'!$B:$B,A61,'Package PO Plan'!$F:$F)+SUMIF('Commercial Events'!$B:$B,A61,'Commercial Events'!$K:$K) -> 0 | E61: =SUMIF(Ledger!$B:$B,A61,Ledger!$H:$H) -> 0 | F61: =MAX(C61,D61,E61) -> 35000 | G61: =C61-F61 -> 0 | H61: Forecast at strongest current commercial baseline unless noted.
A62: 3270 | B62: Roads & Sewers Contingency | C62: 25000 | D62: =SUMIF('Package PO Plan'!$B:$B,A62,'Package PO Plan'!$F:$F)+SUMIF('Commercial Events'!$B:$B,A62,'Commercial Events'!$K:$K) -> 0 | E62: =SUMIF(Ledger!$B:$B,A62,Ledger!$H:$H) -> 0 | F62: =MAX(C62,D62,E62) -> 25000 | G62: =C62-F62 -> 0 | H62: Forecast at strongest current commercial baseline unless noted.
... A81: 4110 | B81: Scaffolding | C81: 82000 | D81: =SUMIF('Package PO Plan'!$B:$B,A81,'Package PO Plan'!$F:$F)+SUMIF('Commercial Events'!$B:$B,A81,'Commercial Events'!$K:$K) -> 78000 | E81: =SUMIF(Ledger!$B:$B,A81,Ledger!$H:$H) -> 30000 | F81: =MAX(C81,D81,E81) -> 82000 | G81: =C81-F81 -> 0 | H81: Forecast at strongest current commercial baseline unless noted.
A82: 4120 | B82: Brickwork | C82: 245000 | D82: =SUMIF('Package PO Plan'!$B:$B,A82,'Package PO Plan'!$F:$F)+SUMIF('Commercial Events'!$B:$B,A82,'Commercial Events'!$K:$K) -> 240000 | E82: =SUMIF(Ledger!$B:$B,A82,Ledger!$H:$H) -> 118000 | F82: 255000 | G82: =C82-F82 -> -10000 | H82: Productivity loss pushes final cost above budget/commitment.
A83: 4130 | B83: Carpentry | C83: 180000 | D83: =SUMIF('Package PO Plan'!$B:$B,A83,'Package PO Plan'!$F:$F)+SUMIF('Commercial Events'!$B:$B,A83,'Commercial Events'!$K:$K) -> 175000 | E83: =SUMIF(Ledger!$B:$B,A83,Ledger!$H:$H) -> 82000 | F83: 175000 | G83: =C83-F83 -> 5000 | H83: Control package: forecast at current PO, delivering £5k saving.
A84: 4140 | B84: Contract Crane Hire | C84: 24000 | D84: =SUMIF('Package PO Plan'!$B:$B,A84,'Package PO Plan'!$F:$F)+SUMIF('Commercial Events'!$B:$B,A84,'Commercial Events'!$K:$K) -> 0 | E84: =SUMIF(Ledger!$B:$B,A84,Ledger!$H:$H) -> 0 | F84: =MAX(C84,D84,E84) -> 24000 | G84: =C84-F84 -> 0 | H84: Forecast at strongest current commercial baseline unless noted.
A85: 4150 | B85: Cladding | C85: 48000 | D85: =SUMIF('Package PO Plan'!$B:$B,A85,'Package PO Plan'!$F:$F)+SUMIF('Commercial Events'!$B:$B,A85,'Commercial Events'!$K:$K) -> 0 | E85: =SUMIF(Ledger!$B:$B,A85,Ledger!$H:$H) -> 0 | F85: =MAX(C85,D85,E85) -> 48000 | G85: =C85-F85 -> 0 | H85: Forecast at strongest current commercial baseline unless noted.
A86: 4160 | B86: Render | C86: 38000 | D86: =SUMIF('Package PO Plan'!$B:$B,A86,'Package PO Plan'!$F:$F)+SUMIF('Commercial Events'!$B:$B,A86,'Commercial Events'!$K:$K) -> 0 | E86: =SUMIF(Ledger!$B:$B,A86,Ledger!$H:$H) -> 0 | F86: =MAX(C86,D86,E86) -> 38000 | G86: =C86-F86 -> 0 | H86: Forecast at strongest current commercial baseline unless noted.
A87: 4170 | B87: Steelwork | C87: 22000 | D87: =SUMIF('Package PO Plan'!$B:$B,A87,'Package PO Plan'!$F:$F)+SUMIF('Commercial Events'!$B:$B,A87,'Commercial Events'!$K:$K) -> 0 | E87: =SUMIF(Ledger!$B:$B,A87,Ledger!$H:$H) -> 0 | F87: =MAX(C87,D87,E87) -> 22000 | G87: =C87-F87 -> 0 | H87: Forecast at strongest current commercial baseline unless noted.
A88: 4180 | B88: Roofing | C88: 115000 | D88: =SUMIF('Package PO Plan'!$B:$B,A88,'Package PO Plan'!$F:$F)+SUMIF('Commercial Events'!$B:$B,A88,'Commercial Events'!$K:$K) -> 110000 | E88: =SUMIF(Ledger!$B:$B,A88,Ledger!$H:$H) -> 42000 | F88: 118000 | G88: =C88-F88 -> -3000 | H88: Pending valley detail expected in full.
A89: 4190 | B89: PV | C89: 72000 | D89: =SUMIF('Package PO Plan'!$B:$B,A89,'Package PO Plan'!$F:$F)+SUMIF('Commercial Events'!$B:$B,A89,'Commercial Events'!$K:$K) -> 0 | E89: =SUMIF(Ledger!$B:$B,A89,Ledger!$H:$H) -> 0 | F89: =MAX(C89,D89,E89) -> 72000 | G89: =C89-F89 -> 0 | H89: Forecast at strongest current commercial baseline unless noted.
A90: 4200 | B90: Windows and Ext. Doors | C90: 125000 | D90: =SUMIF('Package PO Plan'!$B:$B,A90,'Package PO Plan'!$F:$F)+SUMIF('Commercial Events'!$B:$B,A90,'Commercial Events'!$K:$K) -> 119000 | E90: =SUMIF(Ledger!$B:$B,A90,Ledger!$H:$H) -> 46000 | F90: 119000 | G90: =C90-F90 -> 6000 | H90: Approved credit expected to flow through to final cost.
A91: 4210 | B91: Garage Doors | C91: 18000 | D91: =SUMIF('Package PO Plan'!$B:$B,A91,'Package PO Plan'!$F:$F)+SUMIF('Commercial Events'!$B:$B,A91,'Commercial Events'!$K:$K) -> 0 | E91: =SUMIF(Ledger!$B:$B,A91,Ledger!$H:$H) -> 0 | F91: =MAX(C91,D91,E91) -> 18000 | G91: =C91-F91 -> 0 | H91: Forecast at strongest current commercial baseline unless noted.
...

Sheet Expected CVR
A1: Expected CVR — Independent Control Answer
A3: KPI | B3: Value | N3: Section | O3: Budget (£) | P3: Expected FFC (£) | Q3: Variance (£)
A4: Original Budget | B4: =SUM(D14:D223) -> 8065500 | N4: Land | O4: =SUMIF($B$14:$B$223,N4,$D$14:$D$223) -> 1760000 | P4: =SUMIF($B$14:$B$223,N4,$J$14:$J$223) -> 1760000 | Q4: =O4-P4 -> 0
A5: Committed POs | B5: =SUM(E14:E223) -> 2525000 | N5: Fees | O5: =SUMIF($B$14:$B$223,N5,$D$14:$D$223) -> 522000 | P5: =SUMIF($B$14:$B$223,N5,$J$14:$J$223) -> 522000 | Q5: =O5-P5 -> 0
A6: Approved CE Movement | B6: =SUM(F14:F223) -> 53500 | N6: Prelims | O6: =SUMIF($B$14:$B$223,N6,$D$14:$D$223) -> 516500 | P6: =SUMIF($B$14:$B$223,N6,$J$14:$J$223) -> 506500 | Q6: =O6-P6 -> 10000
A7: Ledger Actual | B7: =SUM(H14:H223) -> 3867500 | N7: R&S | O7: =SUMIF($B$14:$B$223,N7,$D$14:$D$223) -> 500000 | P7: =SUMIF($B$14:$B$223,N7,$J$14:$J$223) -> 535000 | Q7: =O7-P7 -> -35000
A8: Expected FFC | B8: =SUM(J14:J223) -> 8115000 | N8: Plot | O8: =SUMIF($B$14:$B$223,N8,$D$14:$D$223) -> 855000 | P8: =SUMIF($B$14:$B$223,N8,$J$14:$J$223) -> 855000 | Q8: =O8-P8 -> 0
A9: Forecast Variance | B9: =SUM(K14:K223) -> -49500 | N9: Super-Structure | O9: =SUMIF($B$14:$B$223,N9,$D$14:$D$223) -> 2948000 | P9: =SUMIF($B$14:$B$223,N9,$J$14:$J$223) -> 2967500 | Q9: =O9-P9 -> -19500
N10: Abnormals | O10: =SUMIF($B$14:$B$223,N10,$D$14:$D$223) -> 413000 | P10: =SUMIF($B$14:$B$223,N10,$J$14:$J$223) -> 418000 | Q10: =O10-P10 -> -5000
N11: Contributions | O11: =SUMIF($B$14:$B$223,N11,$D$14:$D$223) -> 275000 | P11: =SUMIF($B$14:$B$223,N11,$J$14:$J$223) -> 275000 | Q11: =O11-P11 -> 0
N12: Sales | O12: =SUMIF($B$14:$B$223,N12,$D$14:$D$223) -> 276000 | P12: =SUMIF($B$14:$B$223,N12,$J$14:$J$223) -> 276000 | Q12: =O12-P12 -> 0
A13: Cost Code | B13: Sub-Heading | C13: Element | D13: Budget (£) | E13: PO Commitment (£) | F13: Approved CE (£) | G13: Current Commitment (£) | H13: Ledger Actual (£) | I13: Certified Gross (£) | J13: Expected FFC (£) | K13: Variance (£) | L13: Status / Test Note
A14: 1100 | B14: Land | C14: Land Cost | D14: =SUMIF('Original Budget'!$A:$A,A14,'Original Budget'!$E:$E) -> 1650000 | E14: =SUMIF('Package PO Plan'!$B:$B,A14,'Package PO Plan'!$F:$F) -> 0 | F14: =SUMIF('Commercial Events'!$B:$B,A14,'Commercial Events'!$K:$K) -> 0 | G14: =E14+F14 -> 0 | H14: =SUMIF(Ledger!$B:$B,A14,Ledger!$H:$H) -> 1650000 | I14: 0 | J14: ='Forecast Adjustments'!F4 -> 1650000 | K14: =D14-J14 -> 0
A15: 1110 | B15: Land | C15: VAT on Land Purchase | D15: =SUMIF('Original Budget'!$A:$A,A15,'Original Budget'!$E:$E) -> 0 | E15: =SUMIF('Package PO Plan'!$B:$B,A15,'Package PO Plan'!$F:$F) -> 0 | F15: =SUMIF('Commercial Events'!$B:$B,A15,'Commercial Events'!$K:$K) -> 0 | G15: =E15+F15 -> 0 | H15: =SUMIF(Ledger!$B:$B,A15,Ledger!$H:$H) -> 0 | I15: 0 | J15: 0 | K15: =D15-J15 -> 0
A16: 1120 | B16: Land | C16: Stamp Duty - Incl VAT if applicable | D16: =SUMIF('Original Budget'!$A:$A,A16,'Original Budget'!$E:$E) -> 85000 | E16: =SUMIF('Package PO Plan'!$B:$B,A16,'Package PO Plan'!$F:$F) -> 0 | F16: =SUMIF('Commercial Events'!$B:$B,A16,'Commercial Events'!$K:$K) -> 0 | G16: =E16+F16 -> 0 | H16: =SUMIF(Ledger!$B:$B,A16,Ledger!$H:$H) -> 85000 | I16: 0 | J16: ='Forecast Adjustments'!F5 -> 85000 | K16: =D16-J16 -> 0
A17: 1130 | B17: Land | C17: Legal Fees - Solicitor | D17: =SUMIF('Original Budget'!$A:$A,A17,'Original Budget'!$E:$E) -> 25000 | E17: =SUMIF('Package PO Plan'!$B:$B,A17,'Package PO Plan'!$F:$F) -> 0 | F17: =SUMIF('Commercial Events'!$B:$B,A17,'Commercial Events'!$K:$K) -> 0 | G17: =E17+F17 -> 0 | H17: =SUMIF(Ledger!$B:$B,A17,Ledger!$H:$H) -> 22000 | I17: 0 | J17: ='Forecast Adjustments'!F6 -> 25000 | K17: =D17-J17 -> 0
A18: 1140 | B18: Land | C18: Option Fees | D18: =SUMIF('Original Budget'!$A:$A,A18,'Original Budget'!$E:$E) -> 0 | E18: =SUMIF('Package PO Plan'!$B:$B,A18,'Package PO Plan'!$F:$F) -> 0 | F18: =SUMIF('Commercial Events'!$B:$B,A18,'Commercial Events'!$K:$K) -> 0 | G18: =E18+F18 -> 0 | H18: =SUMIF(Ledger!$B:$B,A18,Ledger!$H:$H) -> 0 | I18: 0 | J18: 0 | K18: =D18-J18 -> 0
A19: 1150 | B19: Land | C19: Selling Agent Fees - | D19: =SUMIF('Original Budget'!$A:$A,A19,'Original Budget'!$E:$E) -> 0 | E19: =SUMIF('Package PO Plan'!$B:$B,A19,'Package PO Plan'!$F:$F) -> 0 | F19: =SUMIF('Commercial Events'!$B:$B,A19,'Commercial Events'!$K:$K) -> 0 | G19: =E19+F19 -> 0 | H19: =SUMIF(Ledger!$B:$B,A19,Ledger!$H:$H) -> 0 | I19: 0 | J19: 0 | K19: =D19-J19 -> 0
A20: 1160 | B20: Land | C20: Sundy Land Costs - Overage Payments | D20: =SUMIF('Original Budget'!$A:$A,A20,'Original Budget'!$E:$E) -> 0 | E20: =SUMIF('Package PO Plan'!$B:$B,A20,'Package PO Plan'!$F:$F) -> 0 | F20: =SUMIF('Commercial Events'!$B:$B,A20,'Commercial Events'!$K:$K) -> 0 | G20: =E20+F20 -> 0 | H20: =SUMIF(Ledger!$B:$B,A20,Ledger!$H:$H) -> 0 | I20: 0 | J20: 0 | K20: =D20-J20 -> 0
A21: 1170 | B21: Fees | C21: Planning Application & Supporting Fees | D21: =SUMIF('Original Budget'!$A:$A,A21,'Original Budget'!$E:$E) -> 35000 | E21: =SUMIF('Package PO Plan'!$B:$B,A21,'Package PO Plan'!$F:$F) -> 0 | F21: =SUMIF('Commercial Events'!$B:$B,A21,'Commercial Events'!$K:$K) -> 0 | G21: =E21+F21 -> 0 | H21: =SUMIF(Ledger!$B:$B,A21,Ledger!$H:$H) -> 35000 | I21: 0 | J21: ='Forecast Adjustments'!F7 -> 35000 | K21: =D21-J21 -> 0
A22: 1180 | B22: Fees | C22: Site Investigation | D22: =SUMIF('Original Budget'!$A:$A,A22,'Original Budget'!$E:$E) -> 25000 | E22: =SUMIF('Package PO Plan'!$B:$B,A22,'Package PO Plan'!$F:$F) -> 0 | F22: =SUMIF('Commercial Events'!$B:$B,A22,'Commercial Events'!$K:$K) -> 0 | G22: =E22+F22 -> 0 | H22: =SUMIF(Ledger!$B:$B,A22,Ledger!$H:$H) -> 25000 | I22: 0 | J22: ='Forecast Adjustments'!F8 -> 25000 | K22: =D22-J22 -> 0
A23: 1190 | B23: Fees | C23: Archaeology | D23: =SUMIF('Original Budget'!$A:$A,A23,'Original Budget'!$E:$E) -> 15000 | E23: =SUMIF('Package PO Plan'!$B:$B,A23,'Package PO Plan'!$F:$F) -> 0 | F23: =SUMIF('Commercial Events'!$B:$B,A23,'Commercial Events'!$K:$K) -> 0 | G23: =E23+F23 -> 0 | H23: =SUMIF(Ledger!$B:$B,A23,Ledger!$H:$H) -> 15000 | I23: 0 | J23: ='Forecast Adjustments'!F9 -> 15000 | K23: =D23-J23 -> 0
A24: 1200 | B24: Fees | C24: Contamination | D24: =SUMIF('Original Budget'!$A:$A,A24,'Original Budget'!$E:$E) -> 20000 | E24: =SUMIF('Package PO Plan'!$B:$B,A24,'Package PO Plan'!$F:$F) -> 0 | F24: =SUMIF('Commercial Events'!$B:$B,A24,'Commercial Events'!$K:$K) -> 0 | G24: =E24+F24 -> 0 | H24: =SUMIF(Ledger!$B:$B,A24,Ledger!$H:$H) -> 0 | I24: 0 | J24: ='Forecast Adjustments'!F10 -> 20000 | K24: =D24-J24 -> 0
A25: 1210 | B25: Fees | C25: Design Fees | D25: =SUMIF('Original Budget'!$A:$A,A25,'Original Budget'!$E:$E) -> 40000 | E25: =SUMIF('Package PO Plan'!$B:$B,A25,'Package PO Plan'!$F:$F) -> 0 | F25: =SUMIF('Commercial Events'!$B:$B,A25,'Commercial Events'!$K:$K) -> 0 | G25: =E25+F25 -> 0 | H25: =SUMIF(Ledger!$B:$B,A25,Ledger!$H:$H) -> 28000 | I25: 0 | J25: ='Forecast Adjustments'!F11 -> 40000 | K25: =D25-J25 -> 0
A26: 1220 | B26: Fees | C26: Architects - Post Planning | D26: =SUMIF('Original Budget'!$A:$A,A26,'Original Budget'!$E:$E) -> 55000 | E26: =SUMIF('Package PO Plan'!$B:$B,A26,'Package PO Plan'!$F:$F) -> 0 | F26: =SUMIF('Commercial Events'!$B:$B,A26,'Commercial Events'!$K:$K) -> 0 | G26: =E26+F26 -> 0 | H26: =SUMIF(Ledger!$B:$B,A26,Ledger!$H:$H) -> 25000 | I26: 0 | J26: ='Forecast Adjustments'!F12 -> 55000 | K26: =D26-J26 -> 0
A27: 1230 | B27: Fees | C27: Engineers | D27: =SUMIF('Original Budget'!$A:$A,A27,'Original Budget'!$E:$E) -> 75000 | E27: =SUMIF('Package PO Plan'!$B:$B,A27,'Package PO Plan'!$F:$F) -> 0 | F27: =SUMIF('Commercial Events'!$B:$B,A27,'Commercial Events'!$K:$K) -> 0 | G27: =E27+F27 -> 0 | H27: =SUMIF(Ledger!$B:$B,A27,Ledger!$H:$H) -> 42000 | I27: 0 | J27: ='Forecast Adjustments'!F13 -> 75000 | K27: =D27-J27 -> 0
A28: 1240 | B28: Fees | C28: Surveys | D28: =SUMIF('Original Budget'!$A:$A,A28,'Original Budget'!$E:$E) -> 20000 | E28: =SUMIF('Package PO Plan'!$B:$B,A28,'Package PO Plan'!$F:$F) -> 0 | F28: =SUMIF('Commercial Events'!$B:$B,A28,'Commercial Events'!$K:$K) -> 0 | G28: =E28+F28 -> 0 | H28: =SUMIF(Ledger!$B:$B,A28,Ledger!$H:$H) -> 0 | I28: 0 | J28: ='Forecast Adjustments'!F14 -> 20000 | K28: =D28-J28 -> 0
A29: 1250 | B29: Fees | C29: NHBC Bond Fees | D29: =SUMIF('Original Budget'!$A:$A,A29,'Original Budget'!$E:$E) -> 25000 | E29: =SUMIF('Package PO Plan'!$B:$B,A29,'Package PO Plan'!$F:$F) -> 0 | F29: =SUMIF('Commercial Events'!$B:$B,A29,'Commercial Events'!$K:$K) -> 0 | G29: =E29+F29 -> 0 | H29: =SUMIF(Ledger!$B:$B,A29,Ledger!$H:$H) -> 0 | I29: 0 | J29: ='Forecast Adjustments'!F15 -> 25000 | K29: =D29-J29 -> 0
A30: 1260 | B30: Fees | C30: Insurance | D30: =SUMIF('Original Budget'!$A:$A,A30,'Original Budget'!$E:$E) -> 15000 | E30: =SUMIF('Package PO Plan'!$B:$B,A30,'Package PO Plan'!$F:$F) -> 0 | F30: =SUMIF('Commercial Events'!$B:$B,A30,'Commercial Events'!$K:$K) -> 0 | G30: =E30+F30 -> 0 | H30: =SUMIF(Ledger!$B:$B,A30,Ledger!$H:$H) -> 0 | I30: 0 | J30: ='Forecast Adjustments'!F16 -> 15000 | K30: =D30-J30 -> 0
A31: 1270 | B31: Fees | C31: Planning Consultants | D31: =SUMIF('Original Budget'!$A:$A,A31,'Original Budget'!$E:$E) -> 0 | E31: =SUMIF('Package PO Plan'!$B:$B,A31,'Package PO Plan'!$F:$F) -> 0 | F31: =SUMIF('Commercial Events'!$B:$B,A31,'Commercial Events'!$K:$K) -> 0 | G31: =E31+F31 -> 0 | H31: =SUMIF(Ledger!$B:$B,A31,Ledger!$H:$H) -> 0 | I31: 0 | J31: 0 | K31: =D31-J31 -> 0
A32: 1280 | B32: Fees | C32: Highways Consultants | D32: =SUMIF('Original Budget'!$A:$A,A32,'Original Budget'!$E:$E) -> 20000 | E32: =SUMIF('Package PO Plan'!$B:$B,A32,'Package PO Plan'!$F:$F) -> 0 | F32: =SUMIF('Commercial Events'!$B:$B,A32,'Commercial Events'!$K:$K) -> 0 | G32: =E32+F32 -> 0 | H32: =SUMIF(Ledger!$B:$B,A32,Ledger!$H:$H) -> 8000 | I32: 0 | J32: ='Forecast Adjustments'!F17 -> 20000 | K32: =D32-J32 -> 0
A33: 1290 | B33: Fees | C33: Environmental Consultants | D33: =SUMIF('Original Budget'!$A:$A,A33,'Original Budget'!$E:$E) -> 15000 | E33: =SUMIF('Package PO Plan'!$B:$B,A33,'Package PO Plan'!$F:$F) -> 0 | F33: =SUMIF('Commercial Events'!$B:$B,A33,'Commercial Events'!$K:$K) -> 0 | G33: =E33+F33 -> 0 | H33: =SUMIF(Ledger!$B:$B,A33,Ledger!$H:$H) -> 6000 | I33: 0 | J33: ='Forecast Adjustments'!F18 -> 15000 | K33: =D33-J33 -> 0
A34: 1300 | B34: Fees | C34: M&E Consultants | D34: =SUMIF('Original Budget'!$A:$A,A34,'Original Budget'!$E:$E) -> 10000 | E34: =SUMIF('Package PO Plan'!$B:$B,A34,'Package PO Plan'!$F:$F) -> 0 | F34: =SUMIF('Commercial Events'!$B:$B,A34,'Commercial Events'!$K:$K) -> 0 | G34: =E34+F34 -> 0 | H34: =SUMIF(Ledger!$B:$B,A34,Ledger!$H:$H) -> 0 | I34: 0 | J34: ='Forecast Adjustments'!F19 -> 10000 | K34: =D34-J34 -> 0
A35: 1310 | B35: Fees | C35: Sewers Adoption (s104): | D35: =SUMIF('Original Budget'!$A:$A,A35,'Original Budget'!$E:$E) -> 18000 | E35: =SUMIF('Package PO Plan'!$B:$B,A35,'Package PO Plan'!$F:$F) -> 0 | F35: =SUMIF('Commercial Events'!$B:$B,A35,'Commercial Events'!$K:$K) -> 0 | G35: =E35+F35 -> 0 | H35: =SUMIF(Ledger!$B:$B,A35,Ledger!$H:$H) -> 0 | I35: 0 | J35: ='Forecast Adjustments'!F20 -> 18000 | K35: =D35-J35 -> 0
A36: 1320 | B36: Fees | C36: Highways Adoption (s18/38): | D36: =SUMIF('Original Budget'!$A:$A,A36,'Original Budget'!$E:$E) -> 22000 | E36: =SUMIF('Package PO Plan'!$B:$B,A36,'Package PO Plan'!$F:$F) -> 0 | F36: =SUMIF('Commercial Events'!$B:$B,A36,'Commercial Events'!$K:$K) -> 0 | G36: =E36+F36 -> 0 | H36: =SUMIF(Ledger!$B:$B,A36,Ledger!$H:$H) -> 0 | I36: 0 | J36: ='Forecast Adjustments'!F21 -> 22000 | K36: =D36-J36 -> 0
A37: 1330 | B37: Fees | C37: S278 Fees | D37: =SUMIF('Original Budget'!$A:$A,A37,'Original Budget'!$E:$E) -> 12000 | E37: =SUMIF('Package PO Plan'!$B:$B,A37,'Package PO Plan'!$F:$F) -> 0 | F37: =SUMIF('Commercial Events'!$B:$B,A37,'Commercial Events'!$K:$K) -> 0 | G37: =E37+F37 -> 0 | H37: =SUMIF(Ledger!$B:$B,A37,Ledger!$H:$H) -> 0 | I37: 0 | J37: ='Forecast Adjustments'!F22 -> 12000 | K37: =D37-J37 -> 0
A38: 1340 | B38: Fees | C38: Building Regulation Fees | D38: =SUMIF('Original Budget'!$A:$A,A38,'Original Budget'!$E:$E) -> 22000 | E38: =SUMIF('Package PO Plan'!$B:$B,A38,'Package PO Plan'!$F:$F) -> 0 | F38: =SUMIF('Commercial Events'!$B:$B,A38,'Commercial Events'!$K:$K) -> 0 | G38: =E38+F38 -> 0 | H38: =SUMIF(Ledger!$B:$B,A38,Ledger!$H:$H) -> 0 | I38: 0 | J38: ='Forecast Adjustments'!F23 -> 22000 | K38: =D38-J38 -> 0
A39: 1350 | B39: Fees | C39: Planning Fees | D39: =SUMIF('Original Budget'!$A:$A,A39,'Original Budget'!$E:$E) -> 0 | E39: =SUMIF('Package PO Plan'!$B:$B,A39,'Package PO Plan'!$F:$F) -> 0 | F39: =SUMIF('Commercial Events'!$B:$B,A39,'Commercial Events'!$K:$K) -> 0 | G39: =E39+F39 -> 0 | H39: =SUMIF(Ledger!$B:$B,A39,Ledger!$H:$H) -> 0 | I39: 0 | J39: 0 | K39: =D39-J39 -> 0
A40: 1360 | B40: Fees | C40: SAP Calculations | D40: =SUMIF('Original Budget'!$A:$A,A40,'Original Budget'!$E:$E) -> 10000 | E40: =SUMIF('Package PO Plan'!$B:$B,A40,'Package PO Plan'!$F:$F) -> 0 | F40: =SUMIF('Commercial Events'!$B:$B,A40,'Commercial Events'!$K:$K) -> 0 | G40: =E40+F40 -> 0 | H40: =SUMIF(Ledger!$B:$B,A40,Ledger!$H:$H) -> 0 | I40: 0 | J40: ='Forecast Adjustments'!F24 -> 10000 | K40: =D40-J40 -> 0
A41: 1370 | B41: Fees | C41: Air Tests | D41: =SUMIF('Original Budget'!$A:$A,A41,'Original Budget'!$E:$E) -> 7500 | E41: =SUMIF('Package PO Plan'!$B:$B,A41,'Package PO Plan'!$F:$F) -> 0 | F41: =SUMIF('Commercial Events'!$B:$B,A41,'Commercial Events'!$K:$K) -> 0 | G41: =E41+F41 -> 0 | H41: =SUMIF(Ledger!$B:$B,A41,Ledger!$H:$H) -> 0 | I41: 0 | J41: ='Forecast Adjustments'!F25 -> 7500 | K41: =D41-J41 -> 0
...

Sheet UAT Scenarios
A1: UAT Scenarios — What BuildLite Must Prove
A3: ID | B3: Area | C3: Scenario | D3: Expected Result | E3: Key Codes / Packages | F3: Severity if Wrong | G3: Status | H3: Notes | I3: Control Source
A4: UAT-01 | B4: Budget | C4: Original budget totals agree to Expected CVR | D4: Exact match to workbook total | E4: All | F4: Critical | G4: Not Run | I4: Expected CVR
A5: UAT-02 | B5: Groundworks | C5: Approved £35k CE + £20k pending risk | D5: CCV includes £35k only; pending £20k; FFC £155k on 3100 | E5: 3100 / S-HG001 | F5: Critical | G5: Not Run | I5: CE + Forecast
A6: UAT-03 | B6: Brickwork | C6: Productivity loss despite PO below budget | D6: Budget £245k; current commitment £240k; FFC £255k; £10k adverse | E6: 4120 / S-HG005 | F6: Critical | G6: Not Run | I6: Expected CVR
A7: UAT-04 | B7: Carpentry | C7: Control package with saving | D7: PO/FFC £175k vs £180k budget = £5k favourable | E7: 4130 / S-HG006 | F7: High | G7: Not Run | I7: Expected CVR
A8: UAT-05 | B8: Electrical | C8: Customer upgrade + payable repair origin | D8: CCV £156k; payable events certifiable | E8: 4250 / S-HG011 | F8: Critical | G8: Not Run | I8: CE Register
A9: UAT-06 | B9: Drylining recovery | C9: £4k linked recovery against Drylining | D9: Drylining CCV unchanged; Recovery Position driven by deduction history | E9: 4230 / S-HG009 | F9: Critical | G9: Not Run | I9: Recovery overlay
A10: UAT-07 | B10: Plumbing credit | C10: Approved £6k credit | D10: CCV £179k; forecast saving £11k vs budget | E10: 4240 / S-HG010 | F10: High | G10: Not Run | I10: Expected CVR
A11: UAT-08 | B11: Windows credit | C11: Approved £3k credit | D11: CCV/FFC £119k | E11: 4200 / S-HG008 | F11: Medium | G11: Not Run | I11: Expected CVR
A12: UAT-09 | B12: Roofing pending | C12: £8k submitted variation | D12: Pending £8k; CCV £110k until approval; FFC £118k | E12: 4180 / S-HG007 | F12: High | G12: Not Run | I12: CE + Forecast
A13: UAT-10 | B13: Direct recovery | C13: £1.5k Cleaning direct recovery | D13: Excluded from CCV; shown in Recovery Position; payment-only | E13: 4360 / S-HG015 | F13: Critical | G13: Not Run | I13: Recovery overlay
A14: UAT-11 | B14: Ledger vs certificates | C14: Actual cost differs from certified gross | D14: CVR keeps ledger actual and certified-to-date distinct | E14: Multiple | F14: Critical | G14: Not Run | I14: Ledger/Certificates
A15: UAT-12 | B15: Wrong-code posting | C15: £8.5k on unbudgeted Wardrobes code | D15: CVR exposes £8.5k unbudgeted/adverse cost | E15: 4290 | F15: Critical | G15: Not Run | I15: Ledger
... A26: UAT-23 | B26: Revenue | C26: Final GDV reconciliation | D26: Total final plot revenue equals control workbook exactly | E26: All plots | F26: Critical | G26: Not Run | I26: Plot Schedule Control

Sheet Matrix Index
A1: Hawthorn Gardens — Payment Matrix Pack
A3: PO Number | B3: Cost Code | C3: Element | D3: Supplier | E3: PO Value (£) | F3: Stage Count | G3: File Name | H3: Test Type | I3: Purpose / Expected Behaviour
A4: S-HG001 | B4: 3100 | C4: Groundworker Prelims | D4: J&M Civils Ltd | E4: 115000 | F4: 4 | G4: S-HG001 - 3100 - Groundworker Prelims.xlsx | H4: VALID | I4: Matrix total exactly equals PO value
A5: S-HG002 | B5: 3500 | C5: Service Trenches & Ducts | D5: J&M Civils Ltd | E5: 90000 | F5: 4 | G5: S-HG002 - 3500 - Service Trenches & Ducts.xlsx | H5: VALID | I5: Matrix total exactly equals PO value
A6: S-HG003 | B6: 3520 | C6: Plot Drainage incl Internal Drainage | D6: J&M Civils Ltd | E6: 155000 | F6: 4 | G6: S-HG003 - 3520 - Plot Drainage incl Internal Drainage.xlsx | H6: VALID | I6: Matrix total exactly equals PO value
A7: S-HG004 | B7: 4110 | C7: Scaffolding | D7: HighReach Scaffolding Ltd | E7: 78000 | F7: 4 | G7: S-HG004 - 4110 - Scaffolding.xlsx | H7: VALID | I7: Matrix total exactly equals PO value
A8: S-HG005 | B8: 4120 | C8: Brickwork | D8: Midlands Brickwork Ltd | E8: 235000 | F8: 5 | G8: S-HG005 - 4120 - Brickwork.xlsx | H8: VALID | I8: Matrix total exactly equals PO value
A9: S-HG006 | B9: 4130 | C9: Carpentry | D9: Oakline Carpentry Ltd | E9: 175000 | F9: 5 | G9: S-HG006 - 4130 - Carpentry.xlsx | H9: VALID | I9: Matrix total exactly equals PO value
A10: S-HG007 | B10: 4180 | C10: Roofing | D10: Peak Roofing Ltd | E10: 110000 | F10: 4 | G10: S-HG007 - 4180 - Roofing.xlsx | H10: VALID | I10: Matrix total exactly equals PO value
A11: S-HG008 | B11: 4200 | C11: Windows and Ext. Doors | D11: Clearview Windows Ltd | E11: 122000 | F11: 4 | G11: S-HG008 - 4200 - Windows and Ext. Doors.xlsx | H11: VALID | I11: Matrix total exactly equals PO value
A12: S-HG009 | B12: 4230 | C12: Plastering & Drylining | D12: SmoothFinish Drylining Ltd | E12: 125000 | F12: 4 | G12: S-HG009 - 4230 - Plastering & Drylining.xlsx | H12: VALID | I12: Matrix total exactly equals PO value
A13: S-HG010 | B13: 4240 | C13: Plumbing & Heating | D13: FlowRight Plumbing Ltd | E13: 185000 | F13: 4 | G13: S-HG010 - 4240 - Plumbing & Heating.xlsx | H13: VALID | I13: Matrix total exactly equals PO value
A14: S-HG011 | B14: 4250 | C14: Electrical | D14: Voltwise Electrical Ltd | E14: 140000 | F14: 4 | G14: S-HG011 - 4250 - Electrical.xlsx | H14: VALID | I14: Matrix total exactly equals PO value
A15: S-HG012 | B15: 4260 | C15: Kitchen Fitting | D15: KitchenCraft Installations Ltd | E15: 112000 | F15: 4 | G15: S-HG012 - 4260 - Kitchen Fitting.xlsx | H15: VALID | I15: Matrix total exactly equals PO value
... A24: S-HG011 | B24: 4250 | C24: Electrical | D24: Voltwise Electrical Ltd | E24: 140000 | F24: 4 | G24: NEGATIVE TEST 2 - S-HG011 Electrical - Missing Plot 24.xlsx | H24: NEGATIVE TEST | I24: Plot 24 omitted; imported total £132,440.00 vs PO £140,000.00

Sheet Matrix Stage Profiles
A1: Matrix Stage Profiles — Upload Design
A3: Cost Code | B3: Element | C3: Stage 1 | D3: Stage 2 | E3: Stage 3 | F3: Stage 4 | G3: Stage 5 | H3: Control
A4: 3100 | B4: Groundworker Prelims | C4: Set-up / mobilisation (20%) | D4: Substructure support (30%) | E4: Mid-programme prelims (30%) | F4: Completion / demob (20%) | H4: Stage % = 100%
A5: 3500 | B5: Service Trenches & Ducts | C5: Service trenches (30%) | D5: Duct installation (30%) | E5: Connections (25%) | F5: Backfill / final (15%) | H5: Stage % = 100%
A6: 3520 | B6: Plot Drainage incl Internal Drainage | C6: Below slab drainage (30%) | D6: External drainage (30%) | E6: Testing (20%) | F6: Final connections (20%) | H6: Stage % = 100%
A7: 4110 | B7: Scaffolding | C7: Base Lift (25%) | D7: Second Lift (30%) | E7: Roof Lift (25%) | F7: Strike (20%) | H7: Stage % = 100%
A8: 4120 | B8: Brickwork | C8: DPC / Splash (12%) | D8: First Lift (28%) | E8: Second Lift (30%) | F8: To Roof (22%) | G8: Snag / Final (8%) | H8: Stage % = 100%
A9: 4130 | B9: Carpentry | C9: Joists / Floor (20%) | D9: Roof Carpentry (25%) | E9: First Fix (30%) | F9: Second Fix (20%) | G9: Snag (5%) | H9: Stage % = 100%
A10: 4180 | B10: Roofing | C10: Felt / Batten (25%) | D10: Roof Covering (45%) | E10: Ridge / Verges (20%) | F10: Final (10%) | H10: Stage % = 100%
A11: 4200 | B11: Windows and Ext. Doors | C11: Frames (45%) | D11: Glazing (20%) | E11: External Doors (25%) | F11: Final Adjustments (10%) | H11: Stage % = 100%
A12: 4230 | B12: Plastering & Drylining | C12: Board / Tack (35%) | D12: Skim (35%) | E12: Ceilings (20%) | F12: Snag (10%) | H12: Stage % = 100%
A13: 4240 | B13: Plumbing & Heating | C13: First Fix (35%) | D13: Second Fix (35%) | E13: Sanitaryware (20%) | F13: Commissioning (10%) | H13: Stage % = 100%
A14: 4250 | B14: Electrical | C14: First Fix (35%) | D14: Second Fix (35%) | E14: Accessories (20%) | F14: Test / Certify (10%) | H14: Stage % = 100%
A15: 4260 | B15: Kitchen Fitting | C15: Units (50%) | D15: Worktops (25%) | E15: Appliances / Final (15%) | F15: Snag (10%) | H15: Stage % = 100%
A16: 4340 | B16: Painting & Decoration | C16: Mist Coat (20%) | D16: First Coat (30%) | E16: Final Coat (40%) | F16: Snag (10%) | H16: Stage % = 100%
A17: 4350 | B17: Ceramic Tiling | C17: Bathroom Walls (35%) | D17: Bathroom Floors (25%) | E17: Kitchen / Splashback (25%) | F17: Snag (15%) | H17: Stage % = 100%
A18: 4360 | B18: Cleaning | C18: Build Clean (25%) | D18: Sparkle Clean (40%) | E18: Pre-Handover Clean (25%) | F18: Final / Snag (10%) | H18: Stage % = 100%
A19: 3590 | B19: Fencing | C19: Rear Boundaries (35%) | D19: Side Boundaries (30%) | E19: Frontage (25%) | F19: Snag (10%) | H19: Stage % = 100%
A20: 3640 | B20: Planting | C20: Soil Preparation (25%) | D20: Planting (40%) | E20: Turf / Finish (25%) | F20: Establishment (10%) | H20: Stage % = 100%
A21: 5100 | B21: Demolition / Site Clearance / Remediation | C21: Clearance (25%) | D21: Excavate / Treat (40%) | E21: Backfill / Make Good (20%) | F21: Validation / Closeout (15%) | H21: Stage % = 100%
A22: 5260 | B22: S278 Works | C22: Traffic Management (20%) | D22: Kerbs / Civils (30%) | E22: Surfacing (35%) | F22: Lining / Completion (15%) | H22: Stage % = 100%

Sheet Plot Schedule Control
A1: Hawthorn Gardens — Plot Schedule & Revenue Control
A3: Plot | B3: House Type | C3: Configuration | D3: Beds | E3: GIA ft² | F3: Phase | G3: Tenure | H3: Status | I3: £/ft² | J3: Base Value (£) | K3: Garage | L3: Garage Premium (£) | M3: Plot Premium/(Discount) (£) | N3: Expected Selling Price (£) | O3: Plot Note | P3: Import / Manual | R3: Revenue Control | S3: Value
A4: 1 | B4: The Ash | C4: Semi Detached | D4: 2 | E4: 750 | F4: Phase 1 | G4: Open Market | H4: Not Released | I4: 330 | J4: 247500 | K4: None | L4: 0 | M4: 5000 | N4: 252500 | O4: Corner / larger frontage | P4: Import A-H; set £/ft² / Garage / premiums in BuildLite | R4: Base GDV | S4: 7987000
A5: 2 | B5: The Ash | C5: Semi Detached | D5: 2 | E5: 750 | F5: Phase 1 | G5: Open Market | H5: Not Released | I5: 330 | J5: 247500 | K5: None | L5: 0 | M5: 5000 | N5: 252500 | O5: Corner / larger frontage | P5: Import A-H; set £/ft² / Garage / premiums in BuildLite | R5: Garage Premiums | S5: 292000
A6: 3 | B6: The Ash | C6: Semi Detached | D6: 2 | E6: 750 | F6: Phase 1 | G6: Open Market | H6: Not Released | I6: 330 | J6: 247500 | K6: Single Garage | L6: 12000 | M6: 0 | N6: 259500 | P6: Import A-H; set £/ft² / Garage / premiums in BuildLite | R6: Plot Premiums/(Discounts) | S6: 62500
A7: 4 | B7: The Ash | C7: Semi Detached | D7: 2 | E7: 750 | F7: Phase 1 | G7: Open Market | H7: Not Released | I7: 330 | J7: 247500 | K7: Single Garage | L7: 12000 | M7: 0 | N7: 259500 | P7: Import A-H; set £/ft² / Garage / premiums in BuildLite | R7: Expected Final GDV | S7: 8341500
A8: 5 | B8: The Birch | C8: Semi Detached | D8: 3 | E8: 950 | F8: Phase 1 | G8: Open Market | H8: Not Released | I8: 325 | J8: 308750 | K8: None | L8: 0 | M8: -5000 | N8: 303750 | O8: Close to site entrance | P8: Import A-H; set £/ft² / Garage / premiums in BuildLite | R8: Average £/Unit | S8: 347562.5
A9: 6 | B9: The Birch | C9: Semi Detached | D9: 3 | E9: 950 | F9: Phase 1 | G9: Open Market | H9: Not Released | I9: 325 | J9: 308750 | K9: None | L9: 0 | M9: -5000 | N9: 303750 | O9: Close to site entrance | P9: Import A-H; set £/ft² / Garage / premiums in BuildLite
A10: 7 | B10: The Birch | C10: Semi Detached | D10: 3 | E10: 950 | F10: Phase 1 | G10: Open Market | H10: Not Released | I10: 325 | J10: 308750 | K10: None | L10: 0 | M10: 0 | N10: 308750 | P10: Import A-H; set £/ft² / Garage / premiums in BuildLite
